<?xml version="1.0" encoding="utf-8"?>
<mujoco model="crane_game">
    <compiler angle="radian" autolimits="true"/>
    
    <default>
        <joint armature="1" damping="1" limited="true"/>
        <motor ctrllimited="true" ctrlrange="-1 1"/>
        <default class="track">
            <joint type="slide" damping="100" stiffness="0"/>
            <geom type="box" rgba="0.7 0.7 0.7 1" contype="1" conaffinity="1"/>
        </default>
        <default class="telescope">
            <joint type="slide" damping="100" stiffness="100"/>
            <geom type="box" rgba="0.7 0.7 0.7 1" contype="1" conaffinity="1"/>
        </default>
        <default class="claw">
            <joint type="hinge" damping="10" stiffness="0"/>
            <geom type="box" rgba="0.9 0.2 0.2 1" contype="1" conaffinity="1"/>
        </default>
    </default>

    <contact>
        <exclude body1="x_rail" body2="top_frame"/>
        <exclude body1="y_rail" body2="top_frame"/>
        <exclude body1="z_mechanism" body2="top_frame"/>
        <exclude body1="telescopic_segment" body2="top_frame"/>

        <exclude body1="x_rail" body2="y_rail"/>
        <exclude body1="y_rail" body2="z_mechanism"/>
        <exclude body1="x_rail" body2="z_mechanism"/>
        
        <exclude body1="y_rail" body2="telescopic_segment"/>
        <exclude body1="x_rail" body2="telescopic_segment"/>
        <exclude body1="z_mechanism" body2="telescopic_segment"/>
        
        <!-- Claw exclusions -->
        <exclude body1="claw_base" body2="telescopic_segment"/>
        <exclude body1="claw_left" body2="claw_right"/>
        <exclude body1="claw_base" body2="claw_left"/>
        <exclude body1="claw_base" body2="claw_right"/>
    </contact>
    
    <worldbody>
        <!-- Top frame -->
        <body name="top_frame" pos="0 0 2">
            <geom type="box" size="0.5 0.05 0.02" rgba="0.2 0.2 0.2 1" contype="1" conaffinity="1"/>
            
            <!-- X-axis rail -->
            <body name="x_rail" pos="0 0 0">
                <joint name="x_slider" class="track" axis="1 0 0" range="-0.4 0.4"/>
                <geom type="box" size="0.05 0.5 0.02"/>
                
                <!-- Y-axis rail -->
                <body name="y_rail" pos="0 0 -0.15">
                    <joint name="y_slider" class="track" axis="0 1 0" range="-0.4 0.4"/>
                    <!-- <geom type="box" size="0.02 0.02 0.02" rgba="0.8 0.2 0.2 1"/> -->
                    <geom type="box" size="0.015 0.015 0.15" rgba="0.8 0.8 0.8 1"/>
                    
                    <!-- Second telescopic segment -->
                    <body name="z_mechanism" pos="0 0 -0.01">
                        <joint name="telescopic_segment_joint" class="telescope" axis="0 0 1" range="-.2 0"/>
                        <geom type="box" size="0.012 0.012 0.15" rgba="0.7 0.7 0.7 1"/>
                        
                        <!-- Third (bottom) telescopic segment -->
                        <body name="telescopic_segment" pos="0 0 -0.02">
                            <joint name="z_slider" class="telescope" axis="0 0 1" range="-0.4 0"/>
                            <geom type="box" size="0.01 0.01 0.15" rgba="0.6 0.6 0.6 1"/>
                            
                            <!-- Claw mechanism -->
                            <body name="claw_base" pos="0 0 -0.15">
                                <!-- <joint name="claw_rotate" type="hinge" axis="0 0 1" range="-3.14159 3.14159"/> -->
                                <geom type="box" size="0.05 0.05 0.05" rgba="0.1 0.1 0.8 1"/>
                                
                                <!-- Left claw -->
                                <body name="claw_left" pos="0.05 0 0">
                                    <joint name="claw_left_joint" class="claw" axis="0 1 0" range="0 1.5707"/>
                                    <geom type="cylinder" size="0.01 0.06" pos="0.04 0 0" euler="0 1.5707 0"/>
                                    <geom type="cylinder" size="0.01 0.06" pos="0.1 0 -0.05"/>
                                </body>
                                
                                <!-- Right claw -->
                                <body name="claw_right" pos="-0.05 0 0">
                                    <joint name="claw_right_joint" class="claw" axis="0 1 0" range="-1.5707 0"/>
                                    <geom type="cylinder" size="0.01 0.06" pos="-0.04 0 0" euler="0 1.5707 0"/>
                                    <geom type="cylinder" size="0.01 0.06" pos="-0.1 0 -0.05"/>
                                </body>
                            </body>
                        </body>
                    </body>
                </body>
            </body>
        </body>
    </worldbody>
    
    <equality>
        <!-- Proportional extension constraints -->
        <joint joint1="z_slider" joint2="telescopic_segment_joint" polycoef="0 1.0 0 0 0"/>
        <!-- Synchronize claw movement -->
        <joint joint1="claw_left_joint" joint2="claw_right_joint" polycoef="0 -1 0 0 0"/>
    </equality>
    
    <actuator>
        <position name="x_servo" joint="x_slider" kp="100"/>
        <position name="y_servo" joint="y_slider" kp="100"/>
        <position name="z_servo" joint="z_slider" kp="100"/>
        <!-- <position name="claw_rotate_servo" joint="claw_rotate" kp="50"/> -->
        <position name="claw_grip_servo" joint="claw_left_joint" kp="50"/>
    </actuator>
</mujoco>
