<?xml version="1.0" encoding="utf-8"?>
<mujoco model="crane_game">
    <compiler angle="radian" autolimits="true"/>
    
    <default>
        <joint armature="1" damping="1" limited="true"/>
        <motor ctrllimited="true" ctrlrange="-1 1"/>
        <default class="track">
            <joint type="slide" damping="100" stiffness="0"/>
            <geom type="box" rgba="0.7 0.7 0.7 1" contype="1" conaffinity="1"/>
        </default>
        <default class="telescope">
            <joint type="slide" damping="200" stiffness="0"/>
            <geom type="box" rgba="0.7 0.7 0.7 1" contype="1" conaffinity="1"/>
        </default>
    </default>

    <contact>
        <exclude body1="x_rail" body2="top_frame"/>
        <exclude body1="y_rail" body2="top_frame"/>
        <exclude body1="z_mechanism" body2="top_frame"/>
        <exclude body1="telescopic_segment1" body2="top_frame"/>
        <exclude body1="telescopic_segment2" body2="top_frame"/>
        <exclude body1="telescopic_segment3" body2="top_frame"/>

        <exclude body1="x_rail" body2="y_rail"/>
        <exclude body1="y_rail" body2="z_mechanism"/>
        <exclude body1="x_rail" body2="z_mechanism"/>
        
        <exclude body1="y_rail" body2="telescopic_segment1"/>
        <exclude body1="y_rail" body2="telescopic_segment2"/>
        <exclude body1="y_rail" body2="telescopic_segment3"/>
        <exclude body1="x_rail" body2="telescopic_segment1"/>
        <exclude body1="x_rail" body2="telescopic_segment2"/>
        <exclude body1="x_rail" body2="telescopic_segment3"/>
        <exclude body1="z_mechanism" body2="telescopic_segment1"/>
        <exclude body1="z_mechanism" body2="telescopic_segment2"/>
        <exclude body1="z_mechanism" body2="telescopic_segment3"/>
        
        <exclude body1="telescopic_segment1" body2="telescopic_segment2"/>
        <exclude body1="telescopic_segment1" body2="telescopic_segment3"/>
        <exclude body1="telescopic_segment2" body2="telescopic_segment3"/>
    </contact>
    
    <worldbody>
        <!-- Top frame -->
        <body name="top_frame" pos="0 0 2">
            <geom type="box" size="0.5 0.05 0.02" rgba="0.2 0.2 0.2 1" contype="1" conaffinity="1"/>
            
            <!-- X-axis rail -->
            <body name="x_rail" pos="0 0 0">
                <joint name="x_slider" class="track" axis="1 0 0" range="-0.4 0.4"/>
                <geom type="box" size="0.05 0.5 0.02"/>
                
                <!-- Y-axis rail -->
                <body name="y_rail" pos="0 0 0">
                    <joint name="y_slider" class="track" axis="0 1 0" range="-0.4 0.4"/>
                    <geom type="box" size="0.02 0.02 0.02" rgba="0.8 0.2 0.2 1"/>
                    
                    <!-- Z-axis mechanism with telescoping segments -->
                    <body name="z_mechanism" pos="0 0 0">
                         <!-- First (top) telescopic segment -->
                        <body name="telescopic_segment1" pos="0 0 -0.15">
                            <geom type="box" size="0.015 0.015 0.15" rgba="0.8 0.8 0.8 1"/>
                            
                            <!-- Second telescopic segment -->
                            <body name="telescopic_segment2" pos="0 0 -0.01">
                                <joint name="segment2_joint" class="telescope" axis="0 0 1" range="-.2 0"/>
                                <geom type="box" size="0.012 0.012 0.15" rgba="0.7 0.7 0.7 1"/>
                                
                                <!-- Third (bottom) telescopic segment -->
                                <body name="telescopic_segment3" pos="0 0 -0.02">
                                    <joint name="z_slider" class="telescope" axis="0 0 1" range="-0.4 0"/>
                                    <geom type="box" size="0.01 0.01 0.15" rgba="0.6 0.6 0.6 1"/>
                                </body>
                            </body>
                        </body>
                    </body>
                </body>
            </body>
        </body>
    </worldbody>
    
    <equality>
        <!-- Proportional extension constraints -->
        <joint joint1="z_slider" joint2="segment2_joint" polycoef="0 1.0 0 0 0"/>
    </equality>
    
    <actuator>
        <position name="x_servo" joint="x_slider" kp="100"/>
        <position name="y_servo" joint="y_slider" kp="100"/>
        <position name="z_servo" joint="z_slider" kp="100"/>
    </actuator>
</mujoco>
